Workbook
Name Slicer_month: #N/A
Name Slicer_year: #N/A

Sheet an
F2: companies with maximum total laid off and maximum percentage laid off
A3: Row Labels | B3: Sum of total_laid_off | F3: companies with maximum funds raised millions
A4: 99 | B4: 75 | F4: Companies with the Highest Total Layoffs top 10
A5: #Paid | B5: 19 | F5: industries with the Highest Total Layoffs | Q5: loft | R5: 6 | BH5: Row Labels | BI5: Sum of total_laid_off | CA5: country | CB5: (All)
A6: &Open | B6: 9 | F6: countries with the Highest Total Layoffs | BH6: Amazon | BI6: 18150 | BY6: total laid off
A7: 100 Thieves | B7: 12 | BH7: Google | BI7: 12000 | BK7: Count of company | BW7: Sum of total_laid_off | CA7: Sum of total_laid_off
A8: 10X Genomics | B8: 100 | D8: Row Labels | E8: =VLOOKUP(D:D,A3:B827,2,0) -> Sum of total_laid_off | H8: company with maximum total laid off for years | L8: company with high raised million | P8: company with high total layoffs | AB8: country with high laid_off | BH8: Meta | BI8: 11000 | BK8: 1994 | BW8: 383159 | CA8: 383159
A9: 1stdibs | B9: 70 | C9: =RANK(E:E,E:E) -> #N/A | D9: 99 | E9: =VLOOKUP(D:D,A4:B828,2,0) -> 75 | H9: =VLOOKUP(1,C9:E831,2,0) -> #N/A | I9: =VLOOKUP(1,C9:E831,3,0) -> #N/A | J9: 3 | M9: =VLOOKUP(1,I13:L835, 2,0) -> Byju's | N9: =VLOOKUP(1,I13:L835,4,0) -> 35600 | P9: =VLOOKUP(1,M13:O835,2,0) -> Loft | Q9: =VLOOKUP(1,M13:O835,3,0) -> 6 | W9: industrie with high laid_off | AB9: =VLOOKUP(1,Y12:AA835,2,0) -> United States | AD9: =VLOOKUP(1,Y12:AA835,3,0) -> 256059 | BH9: Salesforce | BI9: 10090 | CB9: =GETPIVOTDATA("total_laid_off",$CA$7) -> 383159
A10: 2TM | B10: 190 | C10: =RANK(E:E,E:E) -> #N/A | D10: #Paid | E10: =VLOOKUP(D:D,A5:B829,2,0) -> 19 | W10: =VLOOKUP(1,T12:V42,2,0) -> #N/A | X10: =VLOOKUP(1,T12:V42,3,0) -> #N/A | BH10: Philips | BI10: 10000 | BW10: =GETPIVOTDATA("total_laid_off",$BW$7) -> 383159
A11: 2U | B11: 0 | C11: =RANK(E:E,E:E) -> #N/A | D11: &Open | E11: =VLOOKUP(D:D,A6:B830,2,0) -> 9 | U11: industry | V11: Sum of total_laid_off | Z11: country | AA11: Sum of total_laid_off | BH11: Microsoft | BI11: 10000
A12: 54gene | B12: 95 | C12: =RANK(E:E,E:E) -> #N/A | D12: 100 Thieves | E12: =VLOOKUP(D:D,A7:B831,2,0) -> 12 | G12: Row Labels | H12: Sum of funds_raised_millions | J12: Row Labels | L12: funds raised million | N12: Row Labels | O12: Count of total_laid_off | T12: =RANK(V:V,V:V) -> #REF! | U12: Aerospace | V12: 661 | Y12: =RANK(AA:AA,AA:AA) -> 23 | Z12: Argentina | AA12: 323 | AQ12: Row Labels | AR12: Sum of funds_raised_millions | BH12: Ericsson | BI12: 8500 | BW12: =GETPIVOTDATA("total_laid_off",$BW$7) -> 383159 | BX12: =GETPIVOTDATA("total_laid_off",$BW$7) -> 383159
A13: 5B Solar | B13: 0 | C13: =RANK(E:E,E:E) -> #N/A | D13: 10X Genomics | E13: =VLOOKUP(D:D,A8:B832,2,0) -> 100 | G13: 99 | H13: 244 | I13: =RANK(L:L,L:L) -> 281 | J13: 99 | L13: =VLOOKUP(G13,G12:H835,2,0) -> 244 | M13: =RANK(O:O,O:O) -> 286 | N13: 99 | O13: 1 | T13: =RANK(V:V,V:V) -> #REF! | U13: Construction | V13: 3863 | Y13: =RANK(AA:AA,AA:AA) -> 14 | Z13: Australia | AA13: 2324 | AI13: Sum of total_laid_off | AL13: Sum of total_laid_off | AQ13: Ola | AR13: 18800 | BH13: Uber | BI13: 7585 | CA13: sum
A14: 6sense | B14: 150 | C14: =RANK(E:E,E:E) -> #N/A | D14: 1stdibs | E14: =VLOOKUP(D:D,A9:B833,2,0) -> 70 | G14: #Paid | H14: 21 | I14: =RANK(L:L,L:L) -> 636 | J14: #Paid | L14: =VLOOKUP(G14,G13:H836,2,0) -> 21 | M14: =RANK(O:O,O:O) -> 286 | N14: #Paid | O14: 1 | T14: =RANK(V:V,V:V) -> #REF! | U14: Consumer | V14: 45182 | Y14: =RANK(AA:AA,AA:AA) -> 19 | Z14: Austria | AA14: 570 | AE14: Sum of total_laid_off | AI14: 383159 | AL14: 383159 | AQ14: Tesla | AR14: 20200 | BH14: Dell | BI14: 6650 | BZ14: Amazon | CA14: 18150
A15: 80 Acres Farms | B15: 0 | C15: =RANK(E:E,E:E) -> #N/A | D15: 2TM | E15: =VLOOKUP(D:D,A10:B834,2,0) -> 190 | G15: &Open | H15: 35 | I15: =RANK(L:L,L:L) -> 587 | J15: &Open | L15: =VLOOKUP(G15,G14:H837,2,0) -> 35 | M15: =RANK(O:O,O:O) -> 286 | N15: &Open | O15: 1 | T15: =RANK(V:V,V:V) -> #REF! | U15: crypto | V15: 10693 | Y15: =RANK(AA:AA,AA:AA) -> 6 | Z15: Brazil | AA15: 10391 | AE15: 383159 | AQ15: Rivian | AR15: 24500 | BH15: Booking.com | BI15: 4601
A16: 8x8 | B16: 355 | C16: =RANK(E:E,E:E) -> #N/A | D16: 2U | E16: =VLOOKUP(D:D,A11:B835,2,0) -> 0 | G16: 100 Thieves | H16: 120 | I16: =RANK(L:L,L:L) -> 406 | J16: 100 Thieves | L16: =VLOOKUP(G16,G15:H838,2,0) -> 120 | M16: =RANK(O:O,O:O) -> 286 | N16: 100 Thieves | O16: 1 | T16: =RANK(V:V,V:V) -> #REF! | U16: Data | V16: 5135 | Y16: =RANK(AA:AA,AA:AA) -> 9 | Z16: Canada | AA16: 6319 | AQ16: Meta | AR16: 26000
A17: 98point6 | B17: 0 | C17: =RANK(E:E,E:E) -> #N/A | D17: 54gene | E17: =VLOOKUP(D:D,A12:B836,2,0) -> 95 | G17: 10X Genomics | H17: 242 | I17: =RANK(L:L,L:L) -> 286 | J17: 10X Genomics | L17: =VLOOKUP(G17,G16:H839,2,0) -> 242 | M17: =RANK(O:O,O:O) -> 286 | N17: 10X Genomics | O17: 1 | T17: =RANK(V:V,V:V) -> #REF! | U17: Education | V17: 13338 | Y17: =RANK(AA:AA,AA:AA) -> 44 | Z17: Chile | AA17: 30 | AQ17: Delivery Hero | AR17: 26500
A18: Abra | B18: 12 | C18: =RANK(E:E,E:E) -> #N/A | D18: 5B Solar | E18: =VLOOKUP(D:D,A13:B837,2,0) -> 0 | G18: 1stdibs | H18: 253 | I18: =RANK(L:L,L:L) -> 275 | J18: 1stdibs | L18: =VLOOKUP(G18,G17:H840,2,0) -> 253 | M18: =RANK(O:O,O:O) -> 286 | N18: 1stdibs | O18: 1 | T18: =RANK(V:V,V:V) -> #REF! | U18: Energy | V18: 802 | Y18: =RANK(AA:AA,AA:AA) -> 11 | Z18: China | AA18: 5905 | AQ18: Bytedance | AR18: 35600
A19: Absci | B19: 40 | C19: =RANK(E:E,E:E) -> #N/A | D19: 6sense | E19: =VLOOKUP(D:D,A14:B838,2,0) -> 150 | G19: 2TM | H19: 500 | I19: =RANK(L:L,L:L) -> 164 | J19: 2TM | L19: =VLOOKUP(G19,G18:H841,2,0) -> 500 | M19: =RANK(O:O,O:O) -> 60 | N19: 2TM | O19: 2 | T19: =RANK(V:V,V:V) -> #REF! | U19: Finance | V19: 28344 | Y19: =RANK(AA:AA,AA:AA) -> 32 | Z19: Colombia | AA19: 130 | AQ19: Twitter | AR19: 38700
A20: Acast | B20: 70 | C20: =RANK(E:E,E:E) -> #N/A | D20: 80 Acres Farms | E20: =VLOOKUP(D:D,A15:B839,2,0) -> 0 | G20: 2U | H20: 426 | I20: =RANK(L:L,L:L) -> 185 | J20: 2U | L20: =VLOOKUP(G20,G19:H842,2,0) -> 426 | M20: =RANK(O:O,O:O) -> 286 | N20: 2U | O20: 1 | T20: =RANK(V:V,V:V) -> #REF! | U20: Fin-Tech | V20: 215 | Y20: =RANK(AA:AA,AA:AA) -> 29 | Z20: Denmark | AA20: 240 | AQ20: WeWork | AR20: 65700
A21: Acko | B21: 45 | C21: =RANK(E:E,E:E) -> #N/A | D21: 8x8 | E21: =VLOOKUP(D:D,A16:B840,2,0) -> 355 | G21: 54gene | H21: 44 | I21: =RANK(L:L,L:L) -> 561 | J21: 54gene | L21: =VLOOKUP(G21,G20:H843,2,0) -> 44 | M21: =RANK(O:O,O:O) -> 286 | N21: 54gene | O21: 1 | T21: =RANK(V:V,V:V) -> #REF! | U21: Fitness | V21: 8748 | Y21: =RANK(AA:AA,AA:AA) -> 27 | Z21: Finland | AA21: 250 | AQ21: Uber | AR21: 123500
A22: Acorns | B22: 50 | C22: =RANK(E:E,E:E) -> #N/A | D22: 98point6 | E22: =VLOOKUP(D:D,A17:B841,2,0) -> 0 | G22: 5B Solar | H22: 12 | I22: =RANK(L:L,L:L) -> 679 | J22: 5B Solar | L22: =VLOOKUP(G22,G21:H844,2,0) -> 12 | M22: =RANK(O:O,O:O) -> 286 | N22: 5B Solar | O22: 1 | T22: =RANK(V:V,V:V) -> #REF! | U22: Food | V22: 22855 | Y22: =RANK(AA:AA,AA:AA) -> 17 | Z22: France | AA22: 915 | AD22: category | AE22: sum of total laid off | AQ22: Netflix | AR22: 487600
A23: Actifio | B23: 54 | C23: =RANK(E:E,E:E) -> #N/A | D23: Abra | E23: =VLOOKUP(D:D,A18:B842,2,0) -> 12 | G23: 6sense | H23: 426 | I23: =RANK(L:L,L:L) -> 185 | J23: 6sense | L23: =VLOOKUP(G23,G22:H845,2,0) -> 426 | M23: =RANK(O:O,O:O) -> 286 | N23: 6sense | O23: 1 | T23: =RANK(V:V,V:V) -> #REF! | U23: Hardware | V23: 13828 | Y23: =RANK(AA:AA,AA:AA) -> 7 | Z23: Germany | AA23: 8701 | AD23: large reduction | AE23: 1399
A24: ActiveCampaign | B24: 0 | C24: =RANK(E:E,E:E) -> #N/A | D24: Absci | E24: =VLOOKUP(D:D,A19:B843,2,0) -> 40 | G24: 80 Acres Farms | H24: 275 | I24: =RANK(L:L,L:L) -> 261 | J24: 80 Acres Farms | L24: =VLOOKUP(G24,G23:H846,2,0) -> 275 | M24: =RANK(O:O,O:O) -> 286 | N24: 80 Acres Farms | O24: 1 | T24: =RANK(V:V,V:V) -> #REF! | U24: Healthcare | V24: 25953 | Y24: =RANK(AA:AA,AA:AA) -> 18 | Z24: Hong Kong | AA24: 730 | AD24: medium reduction | AE24: 69394
A25: Ada | B25: 78 | C25: =RANK(E:E,E:E) -> #N/A | D25: Acast | E25: =VLOOKUP(D:D,A20:B844,2,0) -> 70 | G25: 8x8 | H25: 506 | I25: =RANK(L:L,L:L) -> 162 | J25: 8x8 | L25: =VLOOKUP(G25,G24:H847,2,0) -> 506 | M25: =RANK(O:O,O:O) -> 60 | N25: 8x8 | O25: 2 | T25: =RANK(V:V,V:V) -> #REF! | U25: HR | V25: 2783 | Y25: =RANK(AA:AA,AA:AA) -> 1388 | Z25: Hungary | AA25: 0 | AD25: shutdown | AE25: 7401 | AR25: Row Labels | AS25: Sum of funds_raised_millions
A26: Ada Health | B26: 50 | C26: =RANK(E:E,E:E) -> #N/A | D26: Acko | E26: =VLOOKUP(D:D,A21:B845,2,0) -> 45 | G26: 98point6 | H26: 247 | I26: =RANK(L:L,L:L) -> 277 | J26: 98point6 | L26: =VLOOKUP(G26,G25:H848,2,0) -> 247 | M26: =RANK(O:O,O:O) -> 286 | N26: 98point6 | O26: 1 | T26: =RANK(V:V,V:V) -> #REF! | U26: Infrastructure | V26: 5785 | Y26: =RANK(AA:AA,AA:AA) -> 3 | Z26: India | AA26: 35993 | AD26: small reduction | AE26: 86140 | AR26: Travel | AS26: 33279
A27: Ada Support | B27: 36 | C27: =RANK(E:E,E:E) -> #N/A | D27: Acorns | E27: =VLOOKUP(D:D,A22:B846,2,0) -> 50 | G27: Abra | H27: 106 | I27: =RANK(L:L,L:L) -> 427 | J27: Abra | L27: =VLOOKUP(G27,G26:H849,2,0) -> 106 | M27: =RANK(O:O,O:O) -> 286 | N27: Abra | O27: 1 | T27: =RANK(V:V,V:V) -> #REF! | U27: Legal | V27: 836 | Y27: =RANK(AA:AA,AA:AA) -> 13 | Z27: Indonesia | AA27: 3521 | AD27: unknown | AE27: 29033 | AR27: Other | AS27: 35106
A28: Adaptive Biotechnologies | B28: 100 | C28: =RANK(E:E,E:E) -> #N/A | D28: Actifio | E28: =VLOOKUP(D:D,A23:B847,2,0) -> 54 | G28: Absci | H28: 237 | I28: =RANK(L:L,L:L) -> 290 | J28: Absci | L28: =VLOOKUP(G28,G27:H850,2,0) -> 237 | M28: =RANK(O:O,O:O) -> 286 | N28: Absci | O28: 1 | T28: =RANK(V:V,V:V) -> #REF! | U28: Logistics | V28: 4026 | Y28: =RANK(AA:AA,AA:AA) -> 26 | Z28: Ireland | AA28: 257 | AR28: Healthcare | AS28: 51166
A29: Addepar | B29: 20 | C29: =RANK(E:E,E:E) -> #N/A | D29: ActiveCampaign | E29: =VLOOKUP(D:D,A24:B848,2,0) -> 0 | G29: Acast | H29: 126 | I29: =RANK(L:L,L:L) -> 400 | J29: Acast | L29: =VLOOKUP(G29,G28:H851,2,0) -> 126 | M29: =RANK(O:O,O:O) -> 286 | N29: Acast | O29: 1 | T29: =RANK(V:V,V:V) -> #REF! | U29: Manufacturing | V29: 20 | Y29: =RANK(AA:AA,AA:AA) -> 12 | Z29: Israel | AA29: 3638 | AR29: Retail | AS29: 61688
A30: Adobe | B30: 100 | C30: =RANK(E:E,E:E) -> #N/A | D30: Ada | E30: =VLOOKUP(D:D,A25:B849,2,0) -> 78 | G30: Acko | H30: 143 | I30: =RANK(L:L,L:L) -> 381 | J30: Acko | L30: =VLOOKUP(G30,G29:H852,2,0) -> 143 | M30: =RANK(O:O,O:O) -> 286 | N30: Acko | O30: 1 | T30: =RANK(V:V,V:V) -> #REF! | U30: Marketing | V30: 10258 | Y30: =RANK(AA:AA,AA:AA) -> 1388 | Z30: Italy | AA30: 0 | AR30: Finance | AS30: 95658
A31: AdRoll | B31: 210 | C31: =RANK(E:E,E:E) -> #N/A | D31: Ada Health | E31: =VLOOKUP(D:D,A26:B850,2,0) -> 50 | G31: Acorns | H31: 207 | I31: =RANK(L:L,L:L) -> 313 | J31: Acorns | L31: =VLOOKUP(G31,G30:H853,2,0) -> 207 | M31: =RANK(O:O,O:O) -> 286 | N31: Acorns | O31: 1 | T31: =RANK(V:V,V:V) -> #REF! | U31: Media | V31: 5234 | Y31: =RANK(AA:AA,AA:AA) -> 36 | Z31: Japan | AA31: 85 | AR31: Food | AS31: 96747
A32: Advata | B32: 32 | C32: =RANK(E:E,E:E) -> #N/A | D32: Ada Support | E32: =VLOOKUP(D:D,A27:B851,2,0) -> 36 | G32: Actifio | H32: 352 | I32: =RANK(L:L,L:L) -> 215 | J32: Actifio | L32: =VLOOKUP(G32,G31:H854,2,0) -> 352 | M32: =RANK(O:O,O:O) -> 286 | N32: Actifio | O32: 1 | T32: =RANK(V:V,V:V) -> #REF! | U32: NULL | V32: 0 | Y32: =RANK(AA:AA,AA:AA) -> 21 | Z32: Kenya | AA32: 349 | AR32: Real Estate | AS32: 97598
A33: Adwerx | B33: 40 | C33: =RANK(E:E,E:E) -> #N/A | D33: Adaptive Biotechnologies | E33: =VLOOKUP(D:D,A28:B852,2,0) -> 100 | G33: ActiveCampaign | H33: 360 | I33: =RANK(L:L,L:L) -> 211 | J33: ActiveCampaign | L33: =VLOOKUP(G33,G32:H855,2,0) -> 360 | M33: =RANK(O:O,O:O) -> 286 | N33: ActiveCampaign | O33: 1 | T33: =RANK(V:V,V:V) -> #REF! | U33: Other | V33: 35789 | Y33: =RANK(AA:AA,AA:AA) -> 35 | Z33: Malaysia | AA33: 100 | AR33: Consumer | AS33: 154189
A34: Affirm | B34: 500 | C34: =RANK(E:E,E:E) -> #N/A | D34: Addepar | E34: =VLOOKUP(D:D,A29:B853,2,0) -> 20 | G34: Ada | H34: 190 | I34: =RANK(L:L,L:L) -> 329 | J34: Ada | L34: =VLOOKUP(G34,G33:H856,2,0) -> 190 | M34: =RANK(O:O,O:O) -> 286 | N34: Ada | O34: 1 | T34: =RANK(V:V,V:V) -> #REF! | U34: Product | V34: 1233 | Y34: =RANK(AA:AA,AA:AA) -> 25 | Z34: Mexico | AA34: 270 | AR34: Transportation | AS34: 286810
A35: Afterverse | B35: 60 | C35: =RANK(E:E,E:E) -> #N/A | D35: Adobe | E35: =VLOOKUP(D:D,A30:B854,2,0) -> 100 | G35: Ada Health | H35: 189 | I35: =RANK(L:L,L:L) -> 333 | J35: Ada Health | L35: =VLOOKUP(G35,G34:H857,2,0) -> 189 | M35: =RANK(O:O,O:O) -> 286 | N35: Ada Health | O35: 1 | T35: =RANK(V:V,V:V) -> #REF! | U35: Real Estate | V35: 17565 | Y35: =RANK(AA:AA,AA:AA) -> 30 | Z35: Myanmar | AA35: 200 | AR35: Media | AS35: 504784
A36: Agoda | B36: 1500 | C36: =RANK(E:E,E:E) -> #N/A | D36: AdRoll | E36: =VLOOKUP(D:D,A31:B855,2,0) -> 210 | G36: Ada Support | H36: 60 | I36: =RANK(L:L,L:L) -> 512 | J36: Ada Support | L36: =VLOOKUP(G36,G35:H858,2,0) -> 60 | M36: =RANK(O:O,O:O) -> 286 | N36: Ada Support | O36: 1 | T36: =RANK(V:V,V:V) -> #REF! | U36: Recruiting | V36: 2775 | Y36: =RANK(AA:AA,AA:AA) -> 4 | Z36: Netherlands | AA36: 17220
A37: Ahead | B37: 44 | C37: =RANK(E:E,E:E) -> #N/A | D37: Advata | E37: =VLOOKUP(D:D,A32:B856,2,0) -> 32 | G37: Adaptive Biotechnologies | H37: 406 | I37: =RANK(L:L,L:L) -> 194 | J37: Adaptive Biotechnologies | L37: =VLOOKUP(G37,G36:H859,2,0) -> 406 | M37: =RANK(O:O,O:O) -> 286 | N37: Adaptive Biotechnologies | O37: 1 | T37: =RANK(V:V,V:V) -> #REF! | U37: Retail | V37: 43613 | Y37: =RANK(AA:AA,AA:AA) -> 42 | Z37: New Zealand | AA37: 45
A38: Air | B38: 0 | C38: =RANK(E:E,E:E) -> #N/A | D38: Adwerx | E38: =VLOOKUP(D:D,A33:B857,2,0) -> 40 | G38: Addepar | H38: 491 | I38: =RANK(L:L,L:L) -> 166 | J38: Addepar | L38: =VLOOKUP(G38,G37:H860,2,0) -> 491 | M38: =RANK(O:O,O:O) -> 286 | N38: Addepar | O38: 1 | T38: =RANK(V:V,V:V) -> #REF! | U38: Sales | V38: 13216 | Y38: =RANK(AA:AA,AA:AA) -> 15 | Z38: Nigeria | AA38: 1882
A39: Airbnb | B39: 1930 | C39: =RANK(E:E,E:E) -> #N/A | D39: Affirm | E39: =VLOOKUP(D:D,A34:B858,2,0) -> 500 | G39: Adobe | H39: 2 | I39: =RANK(L:L,L:L) -> 725 | J39: Adobe | L39: =VLOOKUP(G39,G38:H861,2,0) -> 2 | M39: =RANK(O:O,O:O) -> 286 | N39: Adobe | O39: 1 | T39: =RANK(V:V,V:V) -> #REF! | U39: Security | V39: 5979 | Y39: =RANK(AA:AA,AA:AA) -> 1388 | Z39: Pakistan | AA39: 0
A40: Airlift | B40: 0 | C40: =RANK(E:E,E:E) -> #N/A | D40: Afterverse | E40: =VLOOKUP(D:D,A35:B859,2,0) -> 60 | G40: AdRoll | H40: 89 | I40: =RANK(L:L,L:L) -> 457 | J40: AdRoll | L40: =VLOOKUP(G40,G39:H862,2,0) -> 89 | M40: =RANK(O:O,O:O) -> 286 | N40: AdRoll | O40: 1 | T40: =RANK(V:V,V:V) -> #REF! | U40: Support | V40: 3523 | Y40: =RANK(AA:AA,AA:AA) -> 45 | Z40: Poland | AA40: 25
A41: Airtable | B41: 254 | C41: =RANK(E:E,E:E) -> #N/A | D41: Agoda | E41: =VLOOKUP(D:D,A36:B860,2,0) -> 1500 | G41: Advata | H41: 0 | I41: =RANK(L:L,L:L) -> 742 | J41: Advata | L41: =VLOOKUP(G41,G40:H863,2,0) -> 0 | M41: =RANK(O:O,O:O) -> 286 | N41: Advata | O41: 1 | T41: =RANK(V:V,V:V) -> #REF! | U41: Transportation | V41: 33748 | Y41: =RANK(AA:AA,AA:AA) -> 37 | Z41: Romania | AA41: 80
...

Sheet Sheet1
E1: com | F1: funding | G1: layoffs
A2: Meta | B2: 37000 | E2: uber | F2: 123500 | G2: 7585
A3: uber | B3: =GETPIVOTDATA("Sum of funds_raised_millions",an!$BJ$839,"company","Uber")+GETPIVOTDATA("Sum of total_laid_off",an!$BJ$839,"company","Uber") -> 131085 | E3: twitter | F3: 38700 | G3: 3940
A4: peloton | B4: =GETPIVOTDATA("Sum of funds_raised_millions",an!$BJ$839,"company","Peloton")+GETPIVOTDATA("Sum of total_laid_off",an!$BJ$839,"company","Peloton") -> 9784 | E4: bytendance | F4: 35600 | G4: 3750
A5: byju's | B5: =GETPIVOTDATA("Sum of funds_raised_millions",an!$BJ$839,"company","Byju's")+GETPIVOTDATA("Sum of total_laid_off",an!$BJ$839,"company","Byju's") -> 15000 | E5: meta | F5: 26000 | G5: 11000
A6: twitter | B6: =GETPIVOTDATA("Sum of funds_raised_millions",an!$BJ$839,"company","Twitter")+GETPIVOTDATA("Sum of total_laid_off",an!$BJ$839,"company","Twitter") -> 42640 | E6: ola | F6: 18800 | G6: 2800
A7: bytendance | B7: =GETPIVOTDATA("Sum of funds_raised_millions",an!$BJ$839,"company","Bytedance")+GETPIVOTDATA("Sum of total_laid_off",an!$BJ$839,"company","Bytedance") -> 39350
A8: swiggy | B8: =GETPIVOTDATA("Sum of funds_raised_millions",an!$BJ$839,"company","Swiggy")+GETPIVOTDATA("Sum of total_laid_off",an!$BJ$839,"company","Swiggy") -> 14880
A9: ola | B9: =GETPIVOTDATA("Sum of funds_raised_millions",an!$BJ$839,"company","Ola")+GETPIVOTDATA("Sum of total_laid_off",an!$BJ$839,"company","Ola") -> 21600
A10: gopuff | B10: =GETPIVOTDATA("Sum of funds_raised_millions",an!$BJ$839,"company","Gopuff")+GETPIVOTDATA("Sum of total_laid_off",an!$BJ$839,"company","Gopuff") -> 15900

Sheet overview

Sheet analysis

Sheet insights

Sheet Sheet2
M1: =IFERROR(M4,0) -> Consumer | N1: =N4 -> 45182 | P1: =COUNTIF(Table[percentage_laid_off],1) -> 116 | Q1: =SUMPRODUCT((A2:A1996<>"")/COUNTIF(A2:A1996,A2:A1996&"")) -> 1629 | AO1: =IFERROR(GETPIVOTDATA("total_laid_off",$AN$2),0) -> 256059
Q2: =P1/Q1 -> 0.071209331 | AF2: Row Labels | AG2: Sum of total_laid_off | AN2: Row Labels | AO2: Sum of total_laid_off
A3: Row Labels | B3: Sum of total_laid_off | F3: Row Labels | G3: Max of funds_raised_millions | M3: Row Labels | N3: Sum of total_laid_off | U3: Row Labels | V3: Count of company | W3: Count of helped | AF3: Apr | AG3: 31099 | AN3: United States | AO3: 256059
A4: 99 | B4: 75 | D4: =AVERAGEIF(B4:B1630,">"&0) -> 288.74077 | F4: 99 | G4: 244 | I4: =AVERAGEIF(G4:G1630,">"&0) -> 546.31861 | M4: Consumer | N4: 45182 | U4: Funded & Laid Off | V4: 1988 | W4: 0.99699097 | X4: =GETPIVOTDATA("Count of helped",$U$3,"helped","Funded & Laid Off") -> 0.99699097 | AF4: Aug | AG4: 16891 | AN4: Grand Total | AO4: 256059
A5: #Paid | B5: 19 | F5: #Paid | G5: 21 | U5: No Funding Laid Off | V5: 6 | W5: 0.0030090271 | AF5: Dec | AG5: 12381
A6: &Open | B6: 9 | F6: &Open | G6: 35 | U6: Grand Total | V6: 1994 | W6: 1 | AF6: Feb | AG6: 41046
A7: 100 Thieves | B7: 12 | F7: 100 Thieves | G7: 120 | N7: =IFERROR(GETPIVOTDATA("total_laid_off",$M$3),0) -> 0 | AF7: Jan | AG7: 92037
A8: 10X Genomics | B8: 100 | F8: 10X Genomics | G8: 242 | AF8: Jul | AG8: 23415
A9: 1stdibs | B9: 70 | F9: 1stdibs | G9: 253 | AF9: Jun | AG9: 27455
A10: 2TM | B10: 190 | F10: 2TM | G10: 250 | AF10: Mar | AG10: 19859
A11: 2U | B11: 0 | F11: 2U | G11: 426 | AF11: May | AG11: 38689
A12: 54gene | B12: 95 | F12: 54gene | G12: 44 | AF12: Nov | AG12: 55758
A13: 5B Solar | B13: 0 | F13: 5B Solar | G13: 12 | AF13: Oct | AG13: 17878
A14: 6sense | B14: 150 | F14: 6sense | G14: 426 | AF14: Sep | AG14: 6651
A15: 80 Acres Farms | B15: 0 | F15: 80 Acres Farms | G15: 275 | AF15: Grand Total | AG15: 383159
A16: 8x8 | B16: 355 | F16: 8x8 | G16: 253
A17: 98point6 | B17: 0 | F17: 98point6 | G17: 247
A18: Abra | B18: 12 | F18: Abra | G18: 106
A19: Absci | B19: 40 | F19: Absci | G19: 237
A20: Acast | B20: 70 | F20: Acast | G20: 126
A21: Acko | B21: 45 | F21: Acko | G21: 143
A22: Acorns | B22: 50 | F22: Acorns | G22: 207
A23: Actifio | B23: 54 | F23: Actifio | G23: 352
A24: ActiveCampaign | B24: 0 | F24: ActiveCampaign | G24: 360
A25: Ada | B25: 78 | F25: Ada | G25: 190
A26: Ada Health | B26: 50 | F26: Ada Health | G26: 189
A27: Ada Support | B27: 36 | F27: Ada Support | G27: 60
... A1631: Grand Total | B1631: 383159 | F1631: Grand Total | G1631: 121900

Sheet dataset
A1: company | B1: location | C1: industry | D1: total_laid_off | E1: percentage_laid_off | F1: date | G1: month | H1: year | I1: stage | J1: country | K1: funds_raised_millions
A2: Included Health | B2: SF Bay Area | C2: Healthcare | D2: NULL | E2: 0.06 | F2: 44767 | G2: =TEXT(Table[[#This Row],[date]],"mmm") -> Jul | H2: =TEXT(Table[[#This Row],[date]],"yyyy") -> 2022 | I2: Series E | J2: United States | K2: 272
A3: &Open | B3: Dublin | C3: Marketing | D3: 9 | E3: 0.09 | F3: 44882 | G3: =TEXT(Table[[#This Row],[date]],"mmm") -> Nov | H3: =TEXT(Table[[#This Row],[date]],"yyyy") -> 2022 | I3: Series A | J3: Ireland | K3: 35
A4: #Paid | B4: Toronto | C4: Marketing | D4: 19 | E4: 0.17 | F4: 44953 | G4: =TEXT(Table[[#This Row],[date]],"mmm") -> Jan | H4: =TEXT(Table[[#This Row],[date]],"yyyy") -> 2023 | I4: Series B | J4: Canada | K4: 21
A5: 100 Thieves | B5: Los Angeles | C5: Consumer | D5: 12 | E5: NULL | F5: 44755 | G5: =TEXT(Table[[#This Row],[date]],"mmm") -> Jul | H5: =TEXT(Table[[#This Row],[date]],"yyyy") -> 2022 | I5: Series C | J5: United States | K5: 120
A6: 10X Genomics | B6: SF Bay Area | C6: Healthcare | D6: 100 | E6: 0.08 | F6: 44777 | G6: =TEXT(Table[[#This Row],[date]],"mmm") -> Aug | H6: =TEXT(Table[[#This Row],[date]],"yyyy") -> 2022 | I6: Post-IPO | J6: United States | K6: 242
A7: 1stdibs | B7: New York City | C7: Retail | D7: 70 | E7: 0.17 | F7: 43923 | G7: =TEXT(Table[[#This Row],[date]],"mmm") -> Apr | H7: =TEXT(Table[[#This Row],[date]],"yyyy") -> 2020 | I7: Series D | J7: United States | K7: 253
A8: 2TM | B8: Sao Paulo | C8: crypto | D8: 90 | E8: 0.12 | F8: 44713 | G8: =TEXT(Table[[#This Row],[date]],"mmm") -> Jun | H8: =TEXT(Table[[#This Row],[date]],"yyyy") -> 2022 | I8: Unknown | J8: Brazil | K8: 250
A9: 2TM | B9: Sao Paulo | C9: crypto | D9: 100 | E9: 0.15 | F9: 44805 | G9: =TEXT(Table[[#This Row],[date]],"mmm") -> Sep | H9: =TEXT(Table[[#This Row],[date]],"yyyy") -> 2022 | I9: Unknown | J9: Brazil | K9: 250
A10: 2U | B10: Washington D.C. | C10: Education | D10: NULL | E10: 0.2 | F10: 44770 | G10: =TEXT(Table[[#This Row],[date]],"mmm") -> Jul | H10: =TEXT(Table[[#This Row],[date]],"yyyy") -> 2022 | I10: Post-IPO | J10: United States | K10: 426
A11: 54gene | B11: Washington D.C. | C11: Healthcare | D11: 95 | E11: 0.3 | F11: 44802 | G11: =TEXT(Table[[#This Row],[date]],"mmm") -> Aug | H11: =TEXT(Table[[#This Row],[date]],"yyyy") -> 2022 | I11: Series B | J11: United States | K11: 44
A12: 5B Solar | B12: Sydney | C12: Energy | D12: NULL | E12: 0.25 | F12: 44715 | G12: =TEXT(Table[[#This Row],[date]],"mmm") -> Jun | H12: =TEXT(Table[[#This Row],[date]],"yyyy") -> 2022 | I12: Series A | J12: Australia | K12: 12
A13: 6sense | B13: SF Bay Area | C13: Sales | D13: 150 | E13: 0.1 | F13: 44846 | G13: =TEXT(Table[[#This Row],[date]],"mmm") -> Oct | H13: =TEXT(Table[[#This Row],[date]],"yyyy") -> 2022 | I13: Series E | J13: United States | K13: 426
A14: 80 Acres Farms | B14: Cincinnati | C14: Food | D14: NULL | E14: 0.1 | F14: 44944 | G14: =TEXT(Table[[#This Row],[date]],"mmm") -> Jan | H14: =TEXT(Table[[#This Row],[date]],"yyyy") -> 2023 | I14: Unknown | J14: United States | K14: 275
A15: 8x8 | B15: SF Bay Area | C15: Support | D15: 155 | E15: 0.07 | F15: 44944 | G15: =TEXT(Table[[#This Row],[date]],"mmm") -> Jan | H15: =TEXT(Table[[#This Row],[date]],"yyyy") -> 2023 | I15: Post-IPO | J15: United States | K15: 253
A16: 8x8 | B16: SF Bay Area | C16: Support | D16: 200 | E16: 0.09 | F16: 44838 | G16: =TEXT(Table[[#This Row],[date]],"mmm") -> Oct | H16: =TEXT(Table[[#This Row],[date]],"yyyy") -> 2022 | I16: Post-IPO | J16: United States | K16: 253
A17: 98point6 | B17: Seattle | C17: Healthcare | D17: NULL | E17: 0.1 | F17: 44763 | G17: =TEXT(Table[[#This Row],[date]],"mmm") -> Jul | H17: =TEXT(Table[[#This Row],[date]],"yyyy") -> 2022 | I17: Series E | J17: United States | K17: 247
A18: 99 | B18: Sao Paulo | C18: Transportation | D18: 75 | E18: 0.02 | F18: 44824 | G18: =TEXT(Table[[#This Row],[date]],"mmm") -> Sep | H18: =TEXT(Table[[#This Row],[date]],"yyyy") -> 2022 | I18: Acquired | J18: Brazil | K18: 244
A19: Abra | B19: SF Bay Area | C19: crypto | D19: 12 | E19: 0.05 | F19: 44742 | G19: =TEXT(Table[[#This Row],[date]],"mmm") -> Jun | H19: =TEXT(Table[[#This Row],[date]],"yyyy") -> 2022 | I19: Series C | J19: United States | K19: 106
A20: Absci | B20: Vancouver | C20: Healthcare | D20: 40 | E20: NULL | F20: 44782 | G20: =TEXT(Table[[#This Row],[date]],"mmm") -> Aug | H20: =TEXT(Table[[#This Row],[date]],"yyyy") -> 2022 | I20: Post-IPO | J20: United States | K20: 237
A21: Acast | B21: Stockholm | C21: Media | D21: 70 | E21: 0.15 | F21: 44819 | G21: =TEXT(Table[[#This Row],[date]],"mmm") -> Sep | H21: =TEXT(Table[[#This Row],[date]],"yyyy") -> 2022 | I21: Post-IPO | J21: Sweden | K21: 126
A22: Acko | B22: Mumbai | C22: Finance | D22: 45 | E22: 0.09 | F22: 43922 | G22: =TEXT(Table[[#This Row],[date]],"mmm") -> Apr | H22: =TEXT(Table[[#This Row],[date]],"yyyy") -> 2020 | I22: Unknown | J22: India | K22: 143
A23: Acorns | B23: Portland | C23: Finance | D23: 50 | E23: NULL | F23: 43977 | G23: =TEXT(Table[[#This Row],[date]],"mmm") -> May | H23: =TEXT(Table[[#This Row],[date]],"yyyy") -> 2020 | I23: Unknown | J23: United States | K23: 207
A24: Actifio | B24: Boston | C24: Data | D24: 54 | E24: NULL | F24: 44181 | G24: =TEXT(Table[[#This Row],[date]],"mmm") -> Dec | H24: =TEXT(Table[[#This Row],[date]],"yyyy") -> 2020 | I24: Acquired | J24: United States | K24: 352
A25: ActiveCampaign | B25: Chicago | C25: Marketing | D25: NULL | E25: 0.15 | F25: 44837 | G25: =TEXT(Table[[#This Row],[date]],"mmm") -> Oct | H25: =TEXT(Table[[#This Row],[date]],"yyyy") -> 2022 | I25: Series C | J25: United States | K25: 360
A26: Ada | B26: Toronto | C26: Support | D26: 78 | E26: 0.16 | F26: 44824 | G26: =TEXT(Table[[#This Row],[date]],"mmm") -> Sep | H26: =TEXT(Table[[#This Row],[date]],"yyyy") -> 2022 | I26: Series C | J26: Canada | K26: 190
A27: Ada Health | B27: Berlin | C27: Healthcare | D27: 50 | E27: NULL | F27: 44851 | G27: =TEXT(Table[[#This Row],[date]],"mmm") -> Oct | H27: =TEXT(Table[[#This Row],[date]],"yyyy") -> 2022 | I27: Series B | J27: Germany | K27: 189
A28: Ada Support | B28: Toronto | C28: Support | D28: 36 | E28: 0.23 | F28: 43945 | G28: =TEXT(Table[[#This Row],[date]],"mmm") -> Apr | H28: =TEXT(Table[[#This Row],[date]],"yyyy") -> 2020 | I28: Series B | J28: Canada | K28: 60
A29: Adaptive Biotechnologies | B29: Seattle | C29: Healthcare | D29: 100 | E29: 0.12 | F29: 44628 | G29: =TEXT(Table[[#This Row],[date]],"mmm") -> Mar | H29: =TEXT(Table[[#This Row],[date]],"yyyy") -> 2022 | I29: Post-IPO | J29: United States | K29: 406
A30: Addepar | B30: SF Bay Area | C30: Finance | D30: 20 | E30: 0.03 | F30: 44944 | G30: =TEXT(Table[[#This Row],[date]],"mmm") -> Jan | H30: =TEXT(Table[[#This Row],[date]],"yyyy") -> 2023 | I30: Series F | J30: United States | K30: 491
A31: Adobe | B31: SF Bay Area | C31: Marketing | D31: 100 | E31: NULL | F31: 44901 | G31: =TEXT(Table[[#This Row],[date]],"mmm") -> Dec | H31: =TEXT(Table[[#This Row],[date]],"yyyy") -> 2022 | I31: Post-IPO | J31: United States | K31: 2
A32: AdRoll | B32: Salt Lake City | C32: Marketing | D32: 210 | E32: 0.3 | F32: 43921 | G32: =TEXT(Table[[#This Row],[date]],"mmm") -> Mar | H32: =TEXT(Table[[#This Row],[date]],"yyyy") -> 2020 | I32: Series C | J32: United States | K32: 89
A33: Advata | B33: Seattle | C33: Healthcare | D33: 32 | E33: 0.21 | F33: 44862 | G33: =TEXT(Table[[#This Row],[date]],"mmm") -> Oct | H33: =TEXT(Table[[#This Row],[date]],"yyyy") -> 2022 | I33: NULL | J33: United States | K33: NULL
A34: Adwerx | B34: Durham | C34: Marketing | D34: 40 | E34: NULL | F34: 44749 | G34: =TEXT(Table[[#This Row],[date]],"mmm") -> Jul | H34: =TEXT(Table[[#This Row],[date]],"yyyy") -> 2022 | I34: Unknown | J34: United States | K34: 20
A35: Affirm | B35: SF Bay Area | C35: Finance | D35: NULL | E35: 0.01 | F35: 44868 | G35: =TEXT(Table[[#This Row],[date]],"mmm") -> Nov | H35: =TEXT(Table[[#This Row],[date]],"yyyy") -> 2022 | I35: Post-IPO | J35: United States | K35: 1500
A36: Affirm | B36: SF Bay Area | C36: Finance | D36: 500 | E36: 0.19 | F36: 44965 | G36: =TEXT(Table[[#This Row],[date]],"mmm") -> Feb | H36: =TEXT(Table[[#This Row],[date]],"yyyy") -> 2023 | I36: Post-IPO | J36: United States | K36: 1500
A37: Afterverse | B37: Brasilia | C37: Consumer | D37: 60 | E37: 0.2 | F37: 44715 | G37: =TEXT(Table[[#This Row],[date]],"mmm") -> Jun | H37: =TEXT(Table[[#This Row],[date]],"yyyy") -> 2022 | I37: Unknown | J37: Brazil | K37: NULL
A38: Agoda | B38: Singapore | C38: Travel | D38: 1500 | E38: 0.25 | F38: 43969 | G38: =TEXT(Table[[#This Row],[date]],"mmm") -> May | H38: =TEXT(Table[[#This Row],[date]],"yyyy") -> 2020 | I38: Acquired | J38: Singapore | K38: NULL
A39: Ahead | B39: SF Bay Area | C39: Healthcare | D39: 44 | E39: 1 | F39: 44665 | G39: =TEXT(Table[[#This Row],[date]],"mmm") -> Apr | H39: =TEXT(Table[[#This Row],[date]],"yyyy") -> 2022 | I39: Unknown | J39: United States | K39: 9
A40: Air | B40: New York City | C40: Marketing | D40: NULL | E40: 0.16 | F40: 44090 | G40: =TEXT(Table[[#This Row],[date]],"mmm") -> Sep | H40: =TEXT(Table[[#This Row],[date]],"yyyy") -> 2020 | I40: Series A | J40: United States | K40: 18
...

Sheet Dashboard Instructions
